src/fixtures/bundlers.json
{
    "bundles": [
        {
            "maker": {
                "user": {
                    "username": "SwatiM"
                },
                "profile_img_url": "https://storage.googleapis.com/opensea-static/opensea-profile/11.png",
                "address": "0xfe1ebe6fe7ae02a2aae240332f40246ce2e877b7",
                "config": "",
                "discord_id": ""
            },
            "slug": "placestowonder-sOd",
            "assets": [
                {
                    "id": 2871027,
                    "token_id": "1",
                    "num_sales": 0,
                    "background_color": null,
                    "image_url": "",
                    "image_preview_url": null,
                    "image_thumbnail_url": null,
                    "image_original_url": null,
                    "animation_url": null,
                    "animation_original_url": null,
                    "name": null,
                    "description": null,
                    "external_link": null,
                    "asset_contract": {
                        "address": "0x677abe13321337128b73371c5c09e3da75e5b8ce",
                        "asset_contract_type": "semi-fungible",
                        "created_date": "2021-05-27T04:59:18.594683",
                        "name": "Unidentified contract",
                        "nft_version": null,
                        "opensea_version": null,
                        "owner": null,
                        "schema_name": "ERC1155",
                        "symbol": "",
                        "total_supply": null,
                        "description": null,
                        "external_link": null,
                        "image_url": null,
                        "default_to_fiat": false,
                        "dev_buyer_fee_basis_points": 0,
                        "dev_seller_fee_basis_points": 0,
                        "only_proxied_transfers": false,
                        "opensea_buyer_fee_basis_points": 0,
                        "opensea_seller_fee_basis_points": 250,
                        "buyer_fee_basis_points": 0,
                        "seller_fee_basis_points": 250,
                        "payout_address": null
                    },
                    "owner": {
                        "user": {
                            "username": "NullAddress"
                        },
                        "profile_img_url": "https://storage.googleapis.com/opensea-static/opensea-profile/1.png",
                        "address": "5DghaCqZ1zrx6hN8oGFWXLzrB6m2wV1CLLyWLHovdCrsu5W2",
                        "config": "",
                        "discord_id": ""
                    },
                    "permalink": "https://rinkeby.opensea.io/assets/0x677abe13321337128b73371c5c09e3da75e5b8ce/1",
                    "collection": {
                        "banner_image_url": null,
                        "chat_url": null,
                        "created_date": "2021-05-27T04:59:19.137608",
                        "default_to_fiat": false,
                        "description": null,
                        "dev_buyer_fee_basis_points": "0",
                        "dev_seller_fee_basis_points": "0",
                        "discord_url": null,
                        "display_data": {
                            "card_display_style": "contain",
                            "images": []
                        },
                        "external_url": null,
                        "featured": false,
                        "featured_image_url": null,
                        "hidden": true,
                        "safelist_request_status": "not_requested",
                        "image_url": null,
                        "is_subject_to_whitelist": false,
                        "large_image_url": null,
                        "medium_username": null,
                        "name": "Unidentified contract - EyL63sDn54",
                        "only_proxied_transfers": false,
                        "opensea_buyer_fee_basis_points": "0",
                        "opensea_seller_fee_basis_points": "250",
                        "payout_address": null,
                        "require_email": false,
                        "short_description": null,
                        "slug": "unidentified-contract-eyl63sdn54",
                        "telegram_url": null,
                        "twitter_username": null,
                        "instagram_username": null,
                        "wiki_url": null
                    },
                    "decimals": null,
                    "token_metadata": null
                },
                {
                    "id": 2871265,
                    "token_id": "1",
                    "num_sales": 0,
                    "background_color": null,
                    "image_url": "",
                    "image_preview_url": null,
                    "image_thumbnail_url": null,
                    "image_original_url": null,
                    "animation_url": null,
                    "animation_original_url": null,
                    "name": null,
                    "description": null,
                    "external_link": null,
                    "asset_contract": {
                        "address": "0x1bc838272abed478d6a32acf73e613355e118e3b",
                        "asset_contract_type": "semi-fungible",
                        "created_date": "2021-05-27T06:06:44.614324",
                        "name": "Unidentified contract",
                        "nft_version": null,
                        "opensea_version": null,
                        "owner": null,
                        "schema_name": "ERC1155",
                        "symbol": "",
                        "total_supply": null,
                        "description": null,
                        "external_link": null,
                        "image_url": null,
                        "default_to_fiat": false,
                        "dev_buyer_fee_basis_points": 0,
                        "dev_seller_fee_basis_points": 0,
                        "only_proxied_transfers": false,
                        "opensea_buyer_fee_basis_points": 0,
                        "opensea_seller_fee_basis_points": 250,
                        "buyer_fee_basis_points": 0,
                        "seller_fee_basis_points": 250,
                        "payout_address": null
                    },
                    "owner": {
                        "user": {
                            "username": "NullAddress"
                        },
                        "profile_img_url": "https://storage.googleapis.com/opensea-static/opensea-profile/1.png",
                        "address": "5DghaCqZ1zrx6hN8oGFWXLzrB6m2wV1CLLyWLHovdCrsu5W2",
                        "config": "",
                        "discord_id": ""
                    },
                    "permalink": "https://rinkeby.opensea.io/assets/0x1bc838272abed478d6a32acf73e613355e118e3b/1",
                    "collection": {
                        "banner_image_url": null,
                        "chat_url": null,
                        "created_date": "2021-05-27T06:06:45.221754",
                        "default_to_fiat": false,
                        "description": null,
                        "dev_buyer_fee_basis_points": "0",
                        "dev_seller_fee_basis_points": "0",
                        "discord_url": null,
                        "display_data": {
                            "card_display_style": "contain",
                            "images": []
                        },
                        "external_url": null,
                        "featured": false,
                        "featured_image_url": null,
                        "hidden": true,
                        "safelist_request_status": "not_requested",
                        "image_url": null,
                        "is_subject_to_whitelist": false,
