src/fixtures/orders.json
{
  "count": 1,
  "orders": [
    {
      "id": 430329,
      "asset": {
        "id": 38562298,
        "token_id": "2", 
        "num_sales": 0,
        "background_color": null,
        "image_url": "https://lh3.googleusercontent.com/bjT3jlppqW0gnJBnIXaONH5oMZeJ1NyUqEcdebpJo8LSWTzrDWQM_KipUSnhU5s90ceOae0rTEJ-KVOYU31v9cuOb1omj8pkN8kgshs",
        "image_preview_url": "https://lh3.googleusercontent.com/bjT3jlppqW0gnJBnIXaONH5oMZeJ1NyUqEcdebpJo8LSWTzrDWQM_KipUSnhU5s90ceOae0rTEJ-KVOYU31v9cuOb1omj8pkN8kgshs=s250",
        "image_thumbnail_url": "https://lh3.googleusercontent.com/bjT3jlppqW0gnJBnIXaONH5oMZeJ1NyUqEcdebpJo8LSWTzrDWQM_KipUSnhU5s90ceOae0rTEJ-KVOYU31v9cuOb1omj8pkN8kgshs=s128",
        "image_original_url": "https://ipfs.io/ipfs/QmNMk2RDY6tPpJFKGnbLXCQgCviUwuxHdmd45gB24bXVCM",
        "animation_url": null,
        "animation_original_url": null,
        "name": "Eight Minic0inz",
        "description": "['Minic0inz is a fun set of generative art collectables styled in the spirit of Cryptopunks.  Each of the Minic0inz is unique, with a distinct style, name, denomination and Country of Origin.  Join the craze, be a part of something -smaller-, collect your Minic0inz today!  When you purchase this option, you will receive eight freshly minted NFTs from the Minic0inz collection!  Image shown is a placeholder. The actual designs and stats will be revealed after purchase.']",
        "external_link": "http://api.c0inz.com/api/factory/minic0inz/2",
        "asset_contract": {
          "address": "5CMStp6FsUNjU78d9ET5VswnHkMtHR7rUCQQEmFBRNLUsqTL",
          "asset_contract_type": "non-fungible",
          "created_date": "2022-01-31T01:40:16.227245",
          "name": "Minic0inz",
          "nft_version": "3.0",
          "opensea_version": null,
          "owner": 5161397,
          "schema_name": "ERC721",
          "symbol": "MCZ",
          "total_supply": "5",
          "description": null,
          "external_link": null,
          "image_url": null,
          "default_to_fiat": false,
          "dev_buyer_fee_basis_points": 0,
          "dev_seller_fee_basis_points": 0,
          "only_proxied_transfers": false,
          "opensea_buyer_fee_basis_points": 0,
          "opensea_seller_fee_basis_points": 250,
          "buyer_fee_basis_points": 0,
          "seller_fee_basis_points": 250,
          "payout_address": null
        },
        "permalink": "https://testnets.opensea.io/assets/5DghaCqZ1zrx6hN8oGFWXLzrB6m2wV1CLLyWLHovdCrsu5W2/2",
        "collection": {
          "banner_image_url": null,
          "chat_url": null,
          "created_date": "2022-01-31T01:40:17.033248",
          "default_to_fiat": false,
          "description": null,
          "dev_buyer_fee_basis_points": "0",
          "dev_seller_fee_basis_points": "0",
          "discord_url": null,
          "display_data": { "card_display_style": "contain", "images": [] },
          "external_url": null,
          "featured": false,
          "featured_image_url": null,
          "hidden": false,
          "safelist_request_status": "not_requested",
          "image_url": null,
          "is_subject_to_whitelist": false,
          "large_image_url": null,
          "medium_username": null,
          "name": "Minic0inz - ArqDAVGWI2",
          "only_proxied_transfers": false,
          "opensea_buyer_fee_basis_points": "0",
          "opensea_seller_fee_basis_points": "250",
          "payout_address": null,
          "require_email": false,
          "short_description": null,
          "slug": "minic0inz-arqdavgwi2",
          "telegram_url": null,
          "twitter_username": null,
          "instagram_username": null,
          "wiki_url": null
        },
        "decimals": 0,
        "token_metadata": "http://api.c0inz.com/api/factory/minic0inz/2",
        "owner": {
          "user": { "username": "c0inzdotTEST" },
          "profile_img_url": "https://storage.googleapis.com/opensea-static/opensea-profile/16.png",
          "address": "0xf70d79db1997ca11782a9ff70cad401610976216",
          "config": ""
        }
      },
      "asset_bundle": null,
      "created_date": "2022-01-31T08:23:06.137110",
      "closing_date": null,
      "closing_extendable": false,
      "expiration_time": 0,
      "listing_time": 1643617284,
      "order_hash": "0xa6aaabbfdbaa48d2509efc2e1883ce8b4ae3583bacd0387b4705b9341eb11c22",
      "metadata": {
        "asset": {
          "id": "2",
          "address": "5ESMmyRckEmHguGJBJGeywWThWF6stqhrSnXJv4Qk5ZE7jbV"
        },
        "schema": "ERC721"
      },
      "exchange": "5DghaCqZ1zrx6hN8oGFWXLzrB6m2wV1CLLyWLHovdCrsu5W2",
      "maker": {
        "user": { "username": "c0inzdotTEST" },
        "profile_img_url": "https://storage.googleapis.com/opensea-static/opensea-profile/16.png",
        "address": "5FHneW46xGXgs5mUiveU4sbTyGBzmstUspZC92UhjJM694ty",
        "config": ""
      },
      "taker": {
        "user": { "username": "NullAddress" },
        "profile_img_url": "https://storage.googleapis.com/opensea-static/opensea-profile/1.png",
        "address": "5C4hrfjw9DjXZTzV3MwzrrAr9P1MJhSrvWGWqi1eSuyUpnhM",
        "config": ""
      },
      "current_price": "50000000000000000",
      "current_bounty": "500000000000000",
      "bounty_multiple": "0.01",
      "maker_relayer_fee": "250",
      "taker_relayer_fee": "0",
      "maker_protocol_fee": "2",
      "taker_protocol_fee": "2",
      "maker_referrer_fee": "0",
      "fee_recipient": {
        "user": { "username": null },
        "profile_img_url": "https://storage.googleapis.com/opensea-static/opensea-profile/28.png",
        "address": "5C4hrfjw9DjXZTzV3MwzrrAr9P1MJhSrvWGWqi1eSuyUpnhM",
        "config": ""
      },
      "fee_method": 1,
      "side": 1,
      "sale_kind": 0,
      "target": "5HjfpJY1udFo143xVCoGwd2zVB5N4brbySru2yzVfTGy6x9f",
      "how_to_call": 0,
      "calldata": "0x23b872dd000000000000000000000000f70d79db1997ca11782a9ff70cad40161097621600000000000000000000000000000000000000000000000000000000000000000000000000000000000000000000000000000000000000000000000000000002",
      "replacement_pattern": "0x000000000000000000000000000000000000000000000000000000000000000000000000ffffffffffffffffffffffffffffffffffffffffffffffffffffffffffffffff0000000000000000000000000000000000000000000000000000000000000000",
      "static_target": "5DghaCqZ1zrx6hN8oGFWXLzrB6m2wV1CLLyWLHovdCrsu5W2",
      "static_extradata": "",
      "payment_token": "5F3WvKapwKVbgqCbtMRqYzr9obbDAje4H887cpw1ZqLcybN2",
      "payment_token_contract": {
        "id": 2,
        "symbol": "ETH",
        "address": "5F3WvKapwKVbgqCbtMRqYzr9obbDAje4H887cpw1ZqLcybN2",
        "image_url": "https://storage.opensea.io/files/6f8e2979d428180222796ff4a33ab929.svg",
        "name": null,
        "decimals": 18,
        "eth_price": "1.000000000000000",
        "usd_price": "405.649999999999977263"
      },
      "base_price": "50000000000000000",
      "extra": "0",
      "quantity": "1",
      "salt":"0",
      "v": 27,
      "r": "0x09e756cd0b99155bc101181ff38dd81be5e7003629e071aad522cee2786ab399",
      "s": "0x68e986bc155d8e560216a4e91d133cc93b279d76f7b3adbaec83d079caff88ed",
      "approved_on_chain": false,
      "cancelled": false,
      "finalized": false,
      "marked_invalid": false,
      "prefixed_hash": "0x27d9977b86fc9257639c7ccd3fc74977e5818f12f2263d823d467a00bf1a7c3d"
    },
    {
      "id": 430328,
      "asset": {
        "id": 38624835,
        "token_id": "60432257085417945544629360487109577946937860591214672717988575369844098072577",
        "num_sales": 0,
        "background_color": null,
        "image_url": "https://lh3.googleusercontent.com/L5SyDSgJ_PtjCiwJtjGGWLX_RpB_85u5CgU6F4MW-JsrXZcMiI9gvkn0U7TZz5FnBacrdJkRVgHtq5wRI_-KvMB89fuu7UbVrGytyvI",
        "image_preview_url": "https://lh3.googleusercontent.com/L5SyDSgJ_PtjCiwJtjGGWLX_RpB_85u5CgU6F4MW-JsrXZcMiI9gvkn0U7TZz5FnBacrdJkRVgHtq5wRI_-KvMB89fuu7UbVrGytyvI=s250",
        "image_thumbnail_url": "https://lh3.googleusercontent.com/L5SyDSgJ_PtjCiwJtjGGWLX_RpB_85u5CgU6F4MW-JsrXZcMiI9gvkn0U7TZz5FnBacrdJkRVgHtq5wRI_-KvMB89fuu7UbVrGytyvI=s128",
